"""sqlalchemy_database_uri error fix

Revision ID: 1d352a8560e1
Revises: 
Create Date: 2019-07-18 20:37:07.394126

"""
from alembic import op
import sqlalchemy as sa


# revision identifiers, used by Alembic.
revision = '1d352a8560e1'
down_revision = None
branch_labels = None
depends_on = None


def upgrade():
    # ### commands auto generated by Alembic - please adjust! ###
    op.create_table('users',
    sa.Column('id', sa.Integer(), nullable=False),
    sa.Column('email', sa.String(length=64), nullable=True),
    sa.Column('username', sa.String(length=64), nullable=True),
    sa.Column('password_hash', sa.String(length=128), nullable=True),
    sa.PrimaryKeyConstraint('id')
    )
    op.create_index(op.f('ix_users_email'), 'users', ['email'], unique=True)
    op.create_index(op.f('ix_users_username'), 'users', ['username'], unique=True)
    # ### end Alembic commands ###


def downgrade():
    # ### commands auto generated by Alembic - please adjust! ###
    op.drop_index(op.f('ix_users_username'), table_name='users')
    op.drop_index(op.f('ix_users_email'), table_name='users')
    op.drop_table('users')
    # ### end Alembic commands ###
